<?xml version="1.0"?>
<robot name="cart">
    <material name="white">
        <color rgba="1 1 1 1" />
    </material>

    <material name="orange">
        <color rgba="1 0.3 0.1 1"/>
    </material>

    <material name="blue">
        <color rgba="0.2 0.2 1 1"/>
    </material>

    <material name="black">
        <color rgba="0 0 0 1"/>
    </material>

    <material name="red">
        <color rgba="1 0 0 1"/>
    </material>

    <!-- CHASSIS LINK -->
    <link name="chassis">
        <visual>
            <origin xyz="0.1675 0 0.069"/>
            <geometry>
                <box size="0.335 0.265 0.1"/>
            </geometry>
            <material name="orange"/>
        </visual>
        <collision>
            <origin xyz="0.1675 0 0.069"/>
            <geometry>
                <box size="0.335 0.265 0.1"/>
            </geometry>
        </collision>
    </link>

    <!-- LEFT WHEEL LINK -->

    <joint name="left_wheel_joint" type="continuous">
        <parent link="chassis"/>
        <child link="left_wheel"/>
        <origin xyz="0.1 0.13 0" rpy="-1.57 0 0" />
        <axis xyz="0 0 1"/>
    </joint>

    <link name="left_wheel">
        <visual>
            <geometry>
                <cylinder radius="0.0625" length="0.02"/>
            </geometry>
            <material name="blue"/>
        </visual>
        <collision>
            <geometry>
                <sphere radius="0.0625"/>
            </geometry>
        </collision>
    </link>

    <!-- RIGHT WHEEL LINK -->

    <joint name="right_wheel_joint" type="continuous">
        <parent link="chassis"/>
        <child link="right_wheel"/>
        <origin xyz="0.1 -0.13 0" rpy="1.57 0 0" />
        <axis xyz="0 0 -1"/>
    </joint>

    <link name="right_wheel">
        <visual>
            <geometry>
                <cylinder radius="0.0625" length="0.02"/>
            </geometry>
            <material name="blue"/>
        </visual>
        <collision>
            <geometry>
                <sphere radius="0.0625"/>
            </geometry>
        </collision>
    </link>

    <!-- CASTER WHEEL LINK -->

    <joint name="caster_wheel_joint" type="fixed">
        <parent link="chassis"/>
        <child link="caster_wheel"/>
        <origin xyz="0.28 0 -0.013"/>
    </joint>


    <link name="caster_wheel">
        <visual>
            <geometry>
                <sphere radius="0.04"/>
            </geometry>
            <material name="white"/>
        </visual>
        <collision>
            <geometry>
                <sphere radius="0.04"/>
            </geometry>
        </collision>
    </link>

    <ros2_control name="mockHardware" type="system">
        <hardware>
          <plugin>mock_components/GenericSystem</plugin>
          <param name="calculate_dynamics">true</param>
          <param name="position_state_following_offset">0.0</param>
          <param name="velocity_state_following_offset">0.0</param>
        </hardware>
      
        <joint name="left_wheel_joint">
            <command_interface name="velocity">
                <param name="min">-10</param>
                <param name="max">10</param>
            </command_interface>
            <state_interface name="position">
                <param name="initial_value">0.0</param>
            </state_interface>
            <state_interface name="velocity">
                <param name="initial_value">0.0</param>
            </state_interface>
        </joint>

        <joint name="right_wheel_joint">
            <command_interface name="velocity">
                <param name="min">-10</param>
                <param name="max">10</param>
            </command_interface>
            <state_interface name="position">
                <param name="initial_value">0.0</param>
            </state_interface>
            <state_interface name="velocity">
                <param name="initial_value">0.0</param>
            </state_interface>
        </joint>
    </ros2_control>

    
</robot>


